Workbook

Sheet 見積もり
T4: 見積番号 | V4: No.0000
B5: 山田 親太朗 | T5: 作成日 | V5: =TODAY() -> 46074
I6: 様 | T6: 有効期限 | V6: =TODAY()+30 -> 46104
K10: =N33 -> 0
E11: 建物基本本体価格 | T11: 円（税込）
H17: 内訳
H20: 建物基本本体価格 | N20: =N67 | S20: 円
H22: オプション工事価格 | N22: =N82 -> 0 | S22: 円
H24: 付帯工事価格 | N24: =N96 -> 0 | S24: 円
H27: 小計 | N27: =SUM(N20:R25) -> 0 | S27: 円
H30: 消費税 | N30: =N27*0.1 -> 0 | S30: 円
H33: 請負金額 | N33: =N27+N30 -> 0 | S33: 円
D38: 物件概要 | H38: 商品名 | P38: 工法 | R38: 在来軸組工法
H41: 基礎仕様 | J41: べた基礎
D46: 床面積 | N46: 備考
D48: 1F | E48: =IFERROR(VLOOKUP(N65,#REF!, 3, FALSE),"") | H48: ㎡ | I48: =IFERROR(E48*0.3025,"") | K48: 坪
D49: 2F | E49: =IFERROR(VLOOKUP(N65,#REF!, 4, FALSE),"") | H49: ㎡ | I49: =IFERROR(E49*0.3025,"") | K49: 坪
D51: 合計 | E51: =IFERROR(E48+E49,"") | H51: ㎡ | I51: =IFERROR(E51*0.3025,"") | K51: 坪
B58: 商品名 | H58: =IF(N65="","",N65)
B64: 工事内容 | J64: 数量 | M64: 単位 | N64: 備考 | U64: 単価 | X64: 金額
B65: 基本本体工事 | J65: - | M65: - | U65: - | X65: =IF($N$65="","",VLOOKUP(N65,#REF!,2,FALSE))
B67: 建物基本本体価格 | N67: =X65 | Z67: 円
B69: 仮設工事 | X69: =IF(U69*J69=0,"",U69*J69)
B70: 基礎工事 | X70: =IF(U70*J70=0,"",U70*J70)
B71: 躯体工事 | X71: =IF(U71*J71=0,"",U71*J71)
B72: 屋根・板金工事 | X72: =IF(U72*J72=0,"",U72*J72)
B73: 外壁工事 | X73: =IF(U73*J73=0,"",U73*J73)
B74: 建具工事 | X74: =IF(U74*J74=0,"",U74*J74)
B75: 内装工事 | X75: =IF(U75*J75=0,"",U75*J75)
B76: 電気設備工事 | X76: =IF(U76*J76=0,"",U76*J76)
B77: 給排水衛生設備 | X77: =IF(U77*J77=0,"",U77*J77)
B78: 空調換気設備 | X78: =IF(U78*J78=0,"",U78*J78)
X79: =IF(U79*J79=0,"",U79*J79)
X80: =IF(U80*J80=0,"",U80*J80)
B82: その他 | N82: =SUM(X69:Z80) -> 0 | Z82: 円
B86: 付帯工事 | M86: 式 | X86: =IFERROR(U86*J86,"") -> 0
B87: 諸経費 | M87: 式 | X87: =IFERROR(U87*J87,"") -> 0
B88: エアコン工事 | M88: 式 | X88: =IFERROR(U88*J88,"") -> 0
B89: 防水工事 | M89: 式 | X89: =IFERROR(U89*J89,"") -> 0
B90: 太陽光 | M90: 式 | X90: =IFERROR(U90*J90,"") -> 0
...

Sheet 建築にかかわる費用
V2: =見積もり!V5 -> 46074
B3: 【1】建築概要
B5: 建築場所
B7: 【2】建築概要
B9: 項目 | I9: 金額 | O9: 備 考
B11: 建物本体価格 | I11: =見積もり!N67 | O11: =IF(見積もり!N65="","",見積もり!N65)
B12: オプション工事費 | I12: =IF(見積もり!N82=0,"",見積もり!N82)
B13: 付帯工事費 | I13: =見積もり!N96 -> 0
B16: 消費税 | I16: =見積もり!Q105
B18: ① 請負金額 | I18: =IF(SUM(I11:M16)=0,"",SUM(I11:M16))
B21: 保証料 | O21: 保証協会にかかる費用です。
B22: 手数料 | O22: 融資実行にかかる費用です。
B23: 火災保険料 | O23: 耐火工法なので、通常の半分ほどでかけられます。
B24: 団信保険料/年 | O24: 100万円/3,361円
B25: つなぎ融資負担費 | O25: 着工から完成するまでの金利負担分です。
B26: その他金融機関費用
B28: ② 金融機関費用合計 | I28: =IF(SUM(I21:M26)=0,"",SUM(I21:M26))
B31: 照明
B32: カーテン
B33: エアコン
B34: 家具
B35: 家電
B36: その他インテリア費用
B38: ③ インテリア費用合計 | I38: =IF(SUM(I31:M36)=0,"",SUM(I31:M36))
B41: 市町村加入金 | O41: 役所からメーターを購入する費用です。
B42: 浄化槽補助金 | O42: 下水道の区域以外は補助金がもらえます。
B43: 本管引込工事 | O43: 水道が敷地に通っていない場合の工事費。
B44: その他水道費用
B46: ④ 水道費用合計 | I46: =IF(SUM(I41:M44)=0,"",SUM(I41:M44))
B49: 土地所有権移転費
B50: 建物表示保存登記費
B51: 土地抵当権設定費
B52: 建物抵当権設定費
B53: その他登記費用
B55: ⑤ 登記費用合計 | I55: =IF(SUM(I49:M53)=0,"",SUM(I49:M53))
B58: 印紙代 | I58: 40400
B59: 地鎮祭玉串料 | I59: 30000
B60: 外構工事費
B61: 解体工事費
B62: 貸付金
...

Sheet 資金計画
B2: 【3】新築の資金計画
B4: 金融機関名
B6: 項目 | M6: 計画 | T6: 備考
B8: 必要資金合計A | M8: =建築にかかわる費用!$S$81 -> 70400 | R8: 円
B9: 自己資金B | R9: 円
B10: 借入金A-B | M10: =M8-M9 -> 70400 | R10: 円
B11: 借入年数 | R11: 年
B12: 借入利率 | R12: ％
B13: 返済額/月C | M13: =IFERROR(PMT(M12/100/12, M11*12, -M10),"") | R13: 円 | T13: 元利均等返済
B17: 太陽光
B19: パネル方角 | E19: 効率 | H19: 枚数 | L19: 枚×270W | P19: 年間発電量 | S19: 売電価格/年 | W19: 備考
B20: 南側 | E20: 1 | K20: 枚 | L20: =H20*270/1000 -> 0 | O20: kw | P20: =L20*1300 -> 0 | R20: kw | S20: =P20*27 -> 0 | V20: 円
B21: 東側 | E21: 0.85 | K21: 枚 | L21: =H21*270/1000 -> 0 | O21: kw | P21: =L21*1300 -> 0 | R21: kw | S21: =P21*27 -> 0 | V21: 円
B22: 西側 | E22: 0.8 | K22: 枚 | L22: =H22*270/1000 -> 0 | O22: kw | P22: =L22*1300 -> 0 | R22: kw | S22: =P22*27 -> 0 | V22: 円
B24: 項目 | M24: 金額 | T24: 備考
B26: 太陽光売電収入/月D | M26: =(S20+S21+S22)/12 -> 0 | R26: 円 | T26: 年間発電料を12ヶ月で割り返した金額
B27: オール電化メリットE | R27: 円 | T27: 1人家族ガス併用と比べた場合
B28: 賞味ローン支払い C-（D+E） | M28: =IFERROR(M13-(M26+M27),"") | R28: 円
B32: 借入金額参考表
B33: 借入金額 | J33: 毎月返済額 | T33: UP率
B35: 19000000 | H35: 円 | J35: 54524 | Q35: 円/月 | T35: =J36-J35 -> 2870 | AA35: 円
B36: 20000000 | H36: 円 | J36: 57394 | Q36: 円/月 | T36: =J37-J36 -> 2869 | AA36: 円
B37: 21000000 | H37: 円 | J37: 60263 | Q37: 円/月 | T37: =J38-J37 -> 2870 | AA37: 円
B38: 22000000 | H38: 円 | J38: 63133 | Q38: 円/月 | T38: =J39-J38 -> 2869.3333 | AA38: 円
B39: 23000000 | H39: 円 | J39: 66002.333 | Q39: 円/月 | T39: =J40-J39 -> 2869.5 | AA39: 円
B40: 24000000 | H40: 円 | J40: 68871.833 | Q40: 円/月 | T40: =J41-J40 -> 2869.5 | AA40: 円
B41: 25000000 | H41: 円 | J41: 71741.333 | Q41: 円/月 | T41: =J42-J41 -> 2869.5 | AA41: 円
B42: 26000000 | H42: 円 | J42: 74610.833 | Q42: 円/月 | T42: =J43-J42 -> 2869.5 | AA42: 円
B43: 27000000 | H43: 円 | J43: 77480.333 | Q43: 円/月 | T43: =J44-J43 -> 2869.5 | AA43: 円
B44: 28000000 | H44: 円 | J44: 80349.833 | Q44: 円/月 | T44: =J45-J44 -> 2869.5 | AA44: 円
B45: 29000000 | H45: 円 | J45: 83219.333 | Q45: 円/月 | T45: =J46-J45 -> 2869.5 | AA45: 円
B46: 30000000 | H46: 円 | J46: 86088.833 | Q46: 円/月 | T46: =J47-J46 -> 2869.5 | AA46: 円
... B55: 39000000 | H55: 円 | J55: 111914.33 | Q55: 円/月 | T55: =J56-J55 -> 2869.5 | AA55: 円
B56: 40000000 | H56: 円 | J56: 114783.83 | Q56: 円/月 | AA56: 円
B58: ※35年返済・金利1.1％で算出
